2025-03-18 16:44:36,243 - __main__ - INFO - شروع راه‌اندازی ربات...
2025-03-18 16:44:36,560 - __main__ - INFO - ربات با موفقیت به سرور تلگرام متصل شد
2025-03-18 16:45:22,119 (__init__.py:1115 MainThread) ERROR - TeleBot: "Infinity polling exception: ('Connection aborted.', RemoteDisconnected('Remote end closed connection without response'))"
2025-03-18 16:45:22,119 - TeleBot - ERROR - Infinity polling exception: ('Connection aborted.', RemoteDisconnected('Remote end closed connection without response'))
2025-03-18 16:45:22,122 (__init__.py:1117 MainThread) ERROR - TeleBot: "Exception traceback:
Traceback (most recent call last):
  File "/home/runner/workspace/.pythonlibs/lib/python3.11/site-packages/urllib3/connectionpool.py", line 787, in urlopen
    response = self._make_request(
               ^^^^^^^^^^^^^^^^^^^
  File "/home/runner/workspace/.pythonlibs/lib/python3.11/site-packages/urllib3/connectionpool.py", line 534, in _make_request
    response = conn.getresponse()
               ^^^^^^^^^^^^^^^^^^
  File "/home/runner/workspace/.pythonlibs/lib/python3.11/site-packages/urllib3/connection.py", line 516, in getresponse
    httplib_response = super().getresponse()
                       ^^^^^^^^^^^^^^^^^^^^^
  File "/nix/store/clx0mcir7qw8zk36zbr4jra789g3knf6-python3-3.11.10/lib/python3.11/http/client.py", line 1395, in getresponse
    response.begin()
  File "/nix/store/clx0mcir7qw8zk36zbr4jra789g3knf6-python3-3.11.10/lib/python3.11/http/client.py", line 325, in begin
    version, status, reason = self._read_status()
                              ^^^^^^^^^^^^^^^^^^^
  File "/nix/store/clx0mcir7qw8zk36zbr4jra789g3knf6-python3-3.11.10/lib/python3.11/http/client.py", line 294, in _read_status
    raise RemoteDisconnected("Remote end closed connection without"
http.client.RemoteDisconnected: Remote end closed connection without response

During handling of the above exception, another exception occurred:

Traceback (most recent call last):
  File "/home/runner/workspace/.pythonlibs/lib/python3.11/site-packages/requests/adapters.py", line 667, in send
    resp = conn.urlopen(
           ^^^^^^^^^^^^^
  File "/home/runner/workspace/.pythonlibs/lib/python3.11/site-packages/urllib3/connectionpool.py", line 841, in urlopen
    retries = retries.increment(
              ^^^^^^^^^^^^^^^^^^
  File "/home/runner/workspace/.pythonlibs/lib/python3.11/site-packages/urllib3/util/retry.py", line 474, in increment
    raise reraise(type(error), error, _stacktrace)
          ^^^^^^^^^^^^^^^^^^^^^^^^^^^^^^^^^^^^^^^^
  File "/home/runner/workspace/.pythonlibs/lib/python3.11/site-packages/urllib3/util/util.py", line 38, in reraise
    raise value.with_traceback(tb)
  File "/home/runner/workspace/.pythonlibs/lib/python3.11/site-packages/urllib3/connectionpool.py", line 787, in urlopen
    response = self._make_request(
               ^^^^^^^^^^^^^^^^^^^
  File "/home/runner/workspace/.pythonlibs/lib/python3.11/site-packages/urllib3/connectionpool.py", line 534, in _make_request
    response = conn.getresponse()
               ^^^^^^^^^^^^^^^^^^
  File "/home/runner/workspace/.pythonlibs/lib/python3.11/site-packages/urllib3/connection.py", line 516, in getresponse
    httplib_response = super().getresponse()
                       ^^^^^^^^^^^^^^^^^^^^^
  File "/nix/store/clx0mcir7qw8zk36zbr4jra789g3knf6-python3-3.11.10/lib/python3.11/http/client.py", line 1395, in getresponse
    response.begin()
  File "/nix/store/clx0mcir7qw8zk36zbr4jra789g3knf6-python3-3.11.10/lib/python3.11/http/client.py", line 325, in begin
    version, status, reason = self._read_status()
                              ^^^^^^^^^^^^^^^^^^^
  File "/nix/store/clx0mcir7qw8zk36zbr4jra789g3knf6-python3-3.11.10/lib/python3.11/http/client.py", line 294, in _read_status
    raise RemoteDisconnected("Remote end closed connection without"
urllib3.exceptions.ProtocolError: ('Connection aborted.', RemoteDisconnected('Remote end closed connection without response'))

During handling of the above exception, another exception occurred:

Traceback (most recent call last):
  File "/home/runner/workspace/.pythonlibs/lib/python3.11/site-packages/telebot/__init__.py", line 1110, in infinity_polling
    self.polling(non_stop=True, timeout=timeout, long_polling_timeout=long_polling_timeout,
  File "/home/runner/workspace/.pythonlibs/lib/python3.11/site-packages/telebot/__init__.py", line 1198, in polling
    self.__threaded_polling(non_stop=non_stop, interval=interval, timeout=timeout, long_polling_timeout=long_polling_timeout,
  File "/home/runner/workspace/.pythonlibs/lib/python3.11/site-packages/telebot/__init__.py", line 1273, in __threaded_polling
    raise e
  File "/home/runner/workspace/.pythonlibs/lib/python3.11/site-packages/telebot/__init__.py", line 1234, in __threaded_polling
    polling_thread.raise_exceptions()
  File "/home/runner/workspace/.pythonlibs/lib/python3.11/site-packages/telebot/util.py", line 111, in raise_exceptions
    raise self.exception_info
  File "/home/runner/workspace/.pythonlibs/lib/python3.11/site-packages/telebot/util.py", line 93, in run
    task(*args, **kwargs)
  File "/home/runner/workspace/.pythonlibs/lib/python3.11/site-packages/telebot/__init__.py", line 688, in __retrieve_updates
    updates = self.get_updates(offset=(self.last_update_id + 1),
             ^^^^^^^^^^^^^^^^^^^^^^^^^^^^^^^^^^^^^^^^^^^^^^^^^^
  File "/home/runner/workspace/.pythonlibs/lib/python3.11/site-packages/telebot/__init__.py", line 660, in get_updates
    json_updates = apihelper.get_updates(
                   ^^^^^^^^^^^^^^^^^^^^^^
  File "/home/runner/workspace/.pythonlibs/lib/python3.11/site-packages/telebot/apihelper.py", line 332, in get_updates
    return _make_request(token, method_url, params=payload)
           ^^^^^^^^^^^^^^^^^^^^^^^^^^^^^^^^^^^^^^^^^^^^^^^^
  File "/home/runner/workspace/.pythonlibs/lib/python3.11/site-packages/telebot/apihelper.py", line 162, in _make_request
    result = _get_req_session().request(
             ^^^^^^^^^^^^^^^^^^^^^^^^^^^
  File "/home/runner/workspace/.pythonlibs/lib/python3.11/site-packages/requests/sessions.py", line 589, in request
    resp = self.send(prep, **send_kwargs)
           ^^^^^^^^^^^^^^^^^^^^^^^^^^^^^^
  File "/home/runner/workspace/.pythonlibs/lib/python3.11/site-packages/requests/sessions.py", line 703, in send
    r = adapter.send(request, **kwargs)
        ^^^^^^^^^^^^^^^^^^^^^^^^^^^^^^^
  File "/home/runner/workspace/.pythonlibs/lib/python3.11/site-packages/requests/adapters.py", line 682, in send
    raise ConnectionError(err, request=request)
requests.exceptions.ConnectionError: ('Connection aborted.', RemoteDisconnected('Remote end closed connection without response'))
"
2025-03-18 16:45:22,122 - TeleBot - ERROR - Exception traceback:
Traceback (most recent call last):
  File "/home/runner/workspace/.pythonlibs/lib/python3.11/site-packages/urllib3/connectionpool.py", line 787, in urlopen
    response = self._make_request(
               ^^^^^^^^^^^^^^^^^^^
  File "/home/runner/workspace/.pythonlibs/lib/python3.11/site-packages/urllib3/connectionpool.py", line 534, in _make_request
    response = conn.getresponse()
               ^^^^^^^^^^^^^^^^^^
  File "/home/runner/workspace/.pythonlibs/lib/python3.11/site-packages/urllib3/connection.py", line 516, in getresponse
    httplib_response = super().getresponse()
                       ^^^^^^^^^^^^^^^^^^^^^
  File "/nix/store/clx0mcir7qw8zk36zbr4jra789g3knf6-python3-3.11.10/lib/python3.11/http/client.py", line 1395, in getresponse
    response.begin()
  File "/nix/store/clx0mcir7qw8zk36zbr4jra789g3knf6-python3-3.11.10/lib/python3.11/http/client.py", line 325, in begin
    version, status, reason = self._read_status()
                              ^^^^^^^^^^^^^^^^^^^
  File "/nix/store/clx0mcir7qw8zk36zbr4jra789g3knf6-python3-3.11.10/lib/python3.11/http/client.py", line 294, in _read_status
    raise RemoteDisconnected("Remote end closed connection without"
http.client.RemoteDisconnected: Remote end closed connection without response

During handling of the above exception, another exception occurred:

Traceback (most recent call last):
  File "/home/runner/workspace/.pythonlibs/lib/python3.11/site-packages/requests/adapters.py", line 667, in send
    resp = conn.urlopen(
           ^^^^^^^^^^^^^
  File "/home/runner/workspace/.pythonlibs/lib/python3.11/site-packages/urllib3/connectionpool.py", line 841, in urlopen
    retries = retries.increment(
              ^^^^^^^^^^^^^^^^^^
  File "/home/runner/workspace/.pythonlibs/lib/python3.11/site-packages/urllib3/util/retry.py", line 474, in increment
    raise reraise(type(error), error, _stacktrace)
          ^^^^^^^^^^^^^^^^^^^^^^^^^^^^^^^^^^^^^^^^
  File "/home/runner/workspace/.pythonlibs/lib/python3.11/site-packages/urllib3/util/util.py", line 38, in reraise
    raise value.with_traceback(tb)
  File "/home/runner/workspace/.pythonlibs/lib/python3.11/site-packages/urllib3/connectionpool.py", line 787, in urlopen
    response = self._make_request(
               ^^^^^^^^^^^^^^^^^^^
  File "/home/runner/workspace/.pythonlibs/lib/python3.11/site-packages/urllib3/connectionpool.py", line 534, in _make_request
    response = conn.getresponse()
               ^^^^^^^^^^^^^^^^^^
  File "/home/runner/workspace/.pythonlibs/lib/python3.11/site-packages/urllib3/connection.py", line 516, in getresponse
    httplib_response = super().getresponse()
                       ^^^^^^^^^^^^^^^^^^^^^
  File "/nix/store/clx0mcir7qw8zk36zbr4jra789g3knf6-python3-3.11.10/lib/python3.11/http/client.py", line 1395, in getresponse
    response.begin()
  File "/nix/store/clx0mcir7qw8zk36zbr4jra789g3knf6-python3-3.11.10/lib/python3.11/http/client.py", line 325, in begin
    version, status, reason = self._read_status()
                              ^^^^^^^^^^^^^^^^^^^
  File "/nix/store/clx0mcir7qw8zk36zbr4jra789g3knf6-python3-3.11.10/lib/python3.11/http/client.py", line 294, in _read_status
    raise RemoteDisconnected("Remote end closed connection without"
urllib3.exceptions.ProtocolError: ('Connection aborted.', RemoteDisconnected('Remote end closed connection without response'))

During handling of the above exception, another exception occurred:

Traceback (most recent call last):
  File "/home/runner/workspace/.pythonlibs/lib/python3.11/site-packages/telebot/__init__.py", line 1110, in infinity_polling
    self.polling(non_stop=True, timeout=timeout, long_polling_timeout=long_polling_timeout,
  File "/home/runner/workspace/.pythonlibs/lib/python3.11/site-packages/telebot/__init__.py", line 1198, in polling
    self.__threaded_polling(non_stop=non_stop, interval=interval, timeout=timeout, long_polling_timeout=long_polling_timeout,
  File "/home/runner/workspace/.pythonlibs/lib/python3.11/site-packages/telebot/__init__.py", line 1273, in __threaded_polling
    raise e
  File "/home/runner/workspace/.pythonlibs/lib/python3.11/site-packages/telebot/__init__.py", line 1234, in __threaded_polling
    polling_thread.raise_exceptions()
  File "/home/runner/workspace/.pythonlibs/lib/python3.11/site-packages/telebot/util.py", line 111, in raise_exceptions
    raise self.exception_info
  File "/home/runner/workspace/.pythonlibs/lib/python3.11/site-packages/telebot/util.py", line 93, in run
    task(*args, **kwargs)
  File "/home/runner/workspace/.pythonlibs/lib/python3.11/site-packages/telebot/__init__.py", line 688, in __retrieve_updates
    updates = self.get_updates(offset=(self.last_update_id + 1),
             ^^^^^^^^^^^^^^^^^^^^^^^^^^^^^^^^^^^^^^^^^^^^^^^^^^
  File "/home/runner/workspace/.pythonlibs/lib/python3.11/site-packages/telebot/__init__.py", line 660, in get_updates
    json_updates = apihelper.get_updates(
                   ^^^^^^^^^^^^^^^^^^^^^^
  File "/home/runner/workspace/.pythonlibs/lib/python3.11/site-packages/telebot/apihelper.py", line 332, in get_updates
    return _make_request(token, method_url, params=payload)
           ^^^^^^^^^^^^^^^^^^^^^^^^^^^^^^^^^^^^^^^^^^^^^^^^
  File "/home/runner/workspace/.pythonlibs/lib/python3.11/site-packages/telebot/apihelper.py", line 162, in _make_request
    result = _get_req_session().request(
             ^^^^^^^^^^^^^^^^^^^^^^^^^^^
  File "/home/runner/workspace/.pythonlibs/lib/python3.11/site-packages/requests/sessions.py", line 589, in request
    resp = self.send(prep, **send_kwargs)
           ^^^^^^^^^^^^^^^^^^^^^^^^^^^^^^
  File "/home/runner/workspace/.pythonlibs/lib/python3.11/site-packages/requests/sessions.py", line 703, in send
    r = adapter.send(request, **kwargs)
        ^^^^^^^^^^^^^^^^^^^^^^^^^^^^^^^
  File "/home/runner/workspace/.pythonlibs/lib/python3.11/site-packages/requests/adapters.py", line 682, in send
    raise ConnectionError(err, request=request)
requests.exceptions.ConnectionError: ('Connection aborted.', RemoteDisconnected('Remote end closed connection without response'))

^C2025-03-18 16:45:39,563 (__init__.py:1121 MainThread) ERROR - TeleBot: "Infinity polling: polling exited"
2025-03-18 16:45:39,563 - TeleBot - ERROR - Infinity polling: polling exited
2025-03-18 16:45:39,564 (__init__.py:1123 MainThread) ERROR - TeleBot: "Break infinity polling"
2025-03-18 16:45:39,564 - TeleBot - ERROR - Break infinity polling